Workbook

Sheet Values Only
A1: Date | B1: Reference | C1: Out | D1: In | E1: Total
A2: 01-04-2026 | B2: RGI8260401791882 | C2: 0 | D2: 675247.78 | E2: 675247.78
A3: 01-04-2026 | B3: EB26040196964896 | C3: 34200 | D3: 0 | E3: 34200
A4: 01-04-2026 | B4: EB26040192058794 | C4: 48450 | D4: 0 | E4: 48450
A5: 01-04-2026 | B5: BICB260401330670 | C5: 126540 | D5: 0 | E5: 126540
A6: 01-04-2026 | B6: BICB260401270233 | C6: 239400 | D6: 0 | E6: 239400
A7: 01-04-2026 | B7: BICB260401559383 | C7: 101175 | D7: 0 | E7: 101175
A8: 01-04-2026 | B8: BICB260401424335 | C8: 112575 | D8: 0 | E8: 112575
A9: 01-04-2026 | B9: BICB260401320295 | C9: 57000 | D9: 0 | E9: 57000
A10: 01-04-2026 | B10: BICB260401235338 | C10: 210900 | D10: 0 | E10: 210900
A11: 01-04-2026 | B11: BICB260401290842 | C11: 95475 | D11: 0 | E11: 95475
A12: 01-04-2026 | B12: BICB260401706372 | C12: 140505 | D12: 0 | E12: 140505
A13: 01-04-2026 | B13: BICB260401128801 | C13: 339150 | D13: 0 | E13: 339150
... A336: 30-06-2026 | B336: RGI8260630925134 | C336: 0 | D336: 536364.61 | E336: 536364.61

Sheet April
A1: Date | B1: Reference | C1: Out | D1: In | E1: Total
A2: 01-04-2026 | B2: RGI8260401791882 | C2: ='Raw Calculations'!E2 -> 0 | D2: ='Raw Calculations'!H2 -> 675247.78 | E2: =C2+D2 -> 675247.78
A3: 01-04-2026 | B3: EB26040196964896 | C3: ='Raw Calculations'!E3 -> 34200 | D3: ='Raw Calculations'!H3 -> 0 | E3: =C3+D3 -> 34200
A4: 01-04-2026 | B4: EB26040192058794 | C4: ='Raw Calculations'!E4 -> 48450 | D4: ='Raw Calculations'!H4 -> 0 | E4: =C4+D4 -> 48450
A5: 01-04-2026 | B5: BICB260401330670 | C5: ='Raw Calculations'!E5 -> 126540 | D5: ='Raw Calculations'!H5 -> 0 | E5: =C5+D5 -> 126540
A6: 01-04-2026 | B6: BICB260401270233 | C6: ='Raw Calculations'!E6 -> 239400 | D6: ='Raw Calculations'!H6 -> 0 | E6: =C6+D6 -> 239400
A7: 01-04-2026 | B7: BICB260401559383 | C7: ='Raw Calculations'!E7 -> 101175 | D7: ='Raw Calculations'!H7 -> 0 | E7: =C7+D7 -> 101175
A8: 01-04-2026 | B8: BICB260401424335 | C8: ='Raw Calculations'!E8 -> 112575 | D8: ='Raw Calculations'!H8 -> 0 | E8: =C8+D8 -> 112575
A9: 01-04-2026 | B9: BICB260401320295 | C9: ='Raw Calculations'!E9 -> 57000 | D9: ='Raw Calculations'!H9 -> 0 | E9: =C9+D9 -> 57000
A10: 01-04-2026 | B10: BICB260401235338 | C10: ='Raw Calculations'!E10 -> 210900 | D10: ='Raw Calculations'!H10 -> 0 | E10: =C10+D10 -> 210900
A11: 01-04-2026 | B11: BICB260401290842 | C11: ='Raw Calculations'!E11 -> 95475 | D11: ='Raw Calculations'!H11 -> 0 | E11: =C11+D11 -> 95475
A12: 01-04-2026 | B12: BICB260401706372 | C12: ='Raw Calculations'!E12 -> 140505 | D12: ='Raw Calculations'!H12 -> 0 | E12: =C12+D12 -> 140505
A13: 01-04-2026 | B13: BICB260401128801 | C13: ='Raw Calculations'!E13 -> 339150 | D13: ='Raw Calculations'!H13 -> 0 | E13: =C13+D13 -> 339150
... A113: 30-04-2026 | B113: 146EI30042657257 | C113: ='Raw Calculations'!E113 -> 0 | D113: ='Raw Calculations'!H113 -> 1645.0533 | E113: =C113+D113 -> 1645.0533

Sheet May
A1: Date | B1: Reference | C1: Out | D1: In | E1: Total
A2: 03-05-2026 | B2: RGI8260503835467 | C2: ='Raw Calculations'!E117 -> 0 | D2: ='Raw Calculations'!H117 -> 1155291.8 | E2: =C2+D2 -> 1155291.8
A3: 03-05-2026 | B3: RGI8260503835562 | C3: ='Raw Calculations'!E118 -> 0 | D3: ='Raw Calculations'!H118 -> 624031.93 | E3: =C3+D3 -> 624031.93
A4: 03-05-2026 | B4: 146EI03052667987 | C4: ='Raw Calculations'!E119 -> 0 | D4: ='Raw Calculations'!H119 -> 7964.8874 | E4: =C4+D4 -> 7964.8874
A5: 03-05-2026 | B5: 146EI03052668003 | C5: ='Raw Calculations'!E120 -> 0 | D5: ='Raw Calculations'!H120 -> 162.4139 | E5: =C5+D5 -> 162.4139
A6: 03-05-2026 | B6: 05626123194279582 | C6: ='Raw Calculations'!E121 -> 159600 | D6: ='Raw Calculations'!H121 -> 0 | E6: =C6+D6 -> 159600
A7: 03-05-2026 | B7: 146CHBK261230003 | C7: ='Raw Calculations'!E122 -> 1995 | D7: ='Raw Calculations'!H122 -> 0 | E7: =C7+D7 -> 1995
A8: 03-05-2026 | B8: 146CHBK261230003 | C8: ='Raw Calculations'!E123 -> 299.25 | D8: ='Raw Calculations'!H123 -> 0 | E8: =C8+D8 -> 299.25
A9: 03-05-2026 | B9: EB26050350012878 | C9: ='Raw Calculations'!E124 -> 117040 | D9: ='Raw Calculations'!H124 -> 0 | E9: =C9+D9 -> 117040
A10: 03-05-2026 | B10: EB26050363156326 | C10: ='Raw Calculations'!E125 -> 31920 | D10: ='Raw Calculations'!H125 -> 0 | E10: =C10+D10 -> 31920
A11: 03-05-2026 | B11: EB26050338801131 | C11: ='Raw Calculations'!E126 -> 45220 | D11: ='Raw Calculations'!H126 -> 0 | E11: =C11+D11 -> 45220
A12: 03-05-2026 | B12: BICB260503501469 | C12: ='Raw Calculations'!E127 -> 638400 | D12: ='Raw Calculations'!H127 -> 0 | E12: =C12+D12 -> 638400
A13: 03-05-2026 | B13: BICB260503627473 | C13: ='Raw Calculations'!E128 -> 30145.78 | D13: ='Raw Calculations'!H128 -> 0 | E13: =C13+D13 -> 30145.78
... A139: 24-05-2026 | B139: 146EI24052601121 | C139: ='Raw Calculations'!E254 -> 0 | D139: ='Raw Calculations'!H254 -> 12505.076 | E139: =C139+D139 -> 12505.076

Sheet June
A1: Date | B1: Reference | C1: Out | D1: In | E1: Total
A2: 01-06-2026 | B2: RGI8260601878583 | C2: ='Raw Calculations'!E258 -> 0 | D2: ='Raw Calculations'!H258 -> 765111.9 | E2: =C2+D2 -> 765111.9
A3: 01-06-2026 | B3: RGI8260601878635 | C3: ='Raw Calculations'!E259 -> 0 | D3: ='Raw Calculations'!H259 -> 898380.51 | E3: =C3+D3 -> 898380.51
A4: 01-06-2026 | B4: 146EI01062642006 | C4: ='Raw Calculations'!E260 -> 0 | D4: ='Raw Calculations'!H260 -> 96777.658 | E4: =C4+D4 -> 96777.658
A5: 01-06-2026 | B5: 146EI01062638571 | C5: ='Raw Calculations'!E261 -> 0 | D5: ='Raw Calculations'!H261 -> 469669.55 | E5: =C5+D5 -> 469669.55
A6: 01-06-2026 | B6: 146EI01062638776 | C6: ='Raw Calculations'!E262 -> 0 | D6: ='Raw Calculations'!H262 -> 464.2968 | E6: =C6+D6 -> 464.2968
A7: 01-06-2026 | B7: 146EI01062638572 | C7: ='Raw Calculations'!E263 -> 0 | D7: ='Raw Calculations'!H263 -> 173346.74 | E7: =C7+D7 -> 173346.74
A8: 01-06-2026 | B8: 146EI01062646286 | C8: ='Raw Calculations'!E264 -> 0 | D8: ='Raw Calculations'!H264 -> 11228.263 | E8: =C8+D8 -> 11228.263
A9: 02-06-2026 | B9: 146EI02062655605 | C9: ='Raw Calculations'!E265 -> 0 | D9: ='Raw Calculations'!H265 -> 108544.06 | E9: =C9+D9 -> 108544.06
A10: 03-06-2026 | B10: RGI8260603881718 | C10: ='Raw Calculations'!E266 -> 0 | D10: ='Raw Calculations'!H266 -> 786732.76 | E10: =C10+D10 -> 786732.76
A11: 04-06-2026 | B11: RGI8260604883398 | C11: ='Raw Calculations'!E267 -> 0 | D11: ='Raw Calculations'!H267 -> 928739.89 | E11: =C11+D11 -> 928739.89
A12: 07-06-2026 | B12: RGI8260607885037 | C12: ='Raw Calculations'!E268 -> 0 | D12: ='Raw Calculations'!H268 -> 749274.52 | E12: =C12+D12 -> 749274.52
A13: 07-06-2026 | B13: RGI8260607885236 | C13: ='Raw Calculations'!E269 -> 0 | D13: ='Raw Calculations'!H269 -> 785100.76 | E13: =C13+D13 -> 785100.76
... A86: 30-06-2026 | B86: RGI8260630925134 | C86: ='Raw Calculations'!E342 -> 0 | D86: ='Raw Calculations'!H342 -> 536364.61 | E86: =C86+D86 -> 536364.61

Sheet Raw Calculations
A1: Date | B1: Reference | C1: Out - old | D1: Multiple | E1: Out - New | F1: In | G1: Multiple | H1: In - New | I1: Total
A2: 01-04-2026 | B2: RGI8260401791882 | C2: 0.00 | D2: 2.85 | E2: =C2*D2 -> 0 | F2: 202,777.11 | G2: 3.33 | H2: =F2*G2 -> 675247.78
A3: 01-04-2026 | B3: EB26040196964896 | C3: 12,000.00 | D3: 2.85 | E3: =C3*D3 -> 34200 | F3: 0.00 | G3: 3.33 | H3: =F3*G3 -> 0
A4: 01-04-2026 | B4: EB26040192058794 | C4: 17,000.00 | D4: 2.85 | E4: =C4*D4 -> 48450 | F4: 0.00 | G4: 3.33 | H4: =F4*G4 -> 0
A5: 01-04-2026 | B5: BICB260401330670 | C5: 44,400.00 | D5: 2.85 | E5: =C5*D5 -> 126540 | F5: 0.00 | G5: 3.33 | H5: =F5*G5 -> 0
A6: 01-04-2026 | B6: BICB260401270233 | C6: 84,000.00 | D6: 2.85 | E6: =C6*D6 -> 239400 | F6: 0.00 | G6: 3.33 | H6: =F6*G6 -> 0
A7: 01-04-2026 | B7: BICB260401559383 | C7: 35,500.00 | D7: 2.85 | E7: =C7*D7 -> 101175 | F7: 0.00 | G7: 3.33 | H7: =F7*G7 -> 0
A8: 01-04-2026 | B8: BICB260401424335 | C8: 39,500.00 | D8: 2.85 | E8: =C8*D8 -> 112575 | F8: 0.00 | G8: 3.33 | H8: =F8*G8 -> 0
A9: 01-04-2026 | B9: BICB260401320295 | C9: 20,000.00 | D9: 2.85 | E9: =C9*D9 -> 57000 | F9: 0.00 | G9: 3.33 | H9: =F9*G9 -> 0
A10: 01-04-2026 | B10: BICB260401235338 | C10: 74,000.00 | D10: 2.85 | E10: =C10*D10 -> 210900 | F10: 0.00 | G10: 3.33 | H10: =F10*G10 -> 0
A11: 01-04-2026 | B11: BICB260401290842 | C11: 33,500.00 | D11: 2.85 | E11: =C11*D11 -> 95475 | F11: 0.00 | G11: 3.33 | H11: =F11*G11 -> 0
A12: 01-04-2026 | B12: BICB260401706372 | C12: 49,300.00 | D12: 2.85 | E12: =C12*D12 -> 140505 | F12: 0.00 | G12: 3.33 | H12: =F12*G12 -> 0
A13: 01-04-2026 | B13: BICB260401128801 | C13: 119,000.00 | D13: 2.85 | E13: =C13*D13 -> 339150 | F13: 0.00 | G13: 3.33 | H13: =F13*G13 -> 0
... A113: 30-04-2026 | B113: 146EI30042657257 | C113: 0.00 | D113: 2.85 | E113: =C113*D113 -> 0 | F113: 494.01 | G113: 3.33 | H113: =F113*G113 -> 1645.0533
C114: =SUM(C2:C113) -> 0 | E114: =SUM(E2:E113) -> 12606230 | H114: =SUM(H2:H113) -> 18376474
A117: 03-05-2026 | B117: RGI8260503835467 | C117: 0.00 | D117: 2.66 | E117: =C117*D117 -> 0 | F117: 320,025.43 | G117: 3.61 | H117: =F117*G117 -> 1155291.8
A118: 03-05-2026 | B118: RGI8260503835562 | C118: 0.00 | D118: 2.66 | E118: =C118*D118 -> 0 | F118: 172,862.03 | G118: 3.61 | H118: =F118*G118 -> 624031.93
A119: 03-05-2026 | B119: 146EI03052667987 | C119: 0.00 | D119: 2.66 | E119: =C119*D119 -> 0 | F119: 2,206.34 | G119: 3.61 | H119: =F119*G119 -> 7964.8874
A120: 03-05-2026 | B120: 146EI03052668003 | C120: 0.00 | D120: 2.66 | E120: =C120*D120 -> 0 | F120: 44.99 | G120: 3.61 | H120: =F120*G120 -> 162.4139
A121: 03-05-2026 | B121: 05626123194279582 | C121: 60,000.00 | D121: 2.66 | E121: =C121*D121 -> 159600 | F121: 0.00 | G121: 3.61 | H121: =F121*G121 -> 0
A122: 03-05-2026 | B122: 146CHBK261230003 | C122: 750.00 | D122: 2.66 | E122: =C122*D122 -> 1995 | F122: 0.00 | G122: 3.61 | H122: =F122*G122 -> 0
A123: 03-05-2026 | B123: 146CHBK261230003 | C123: 112.50 | D123: 2.66 | E123: =C123*D123 -> 299.25 | F123: 0.00 | G123: 3.61 | H123: =F123*G123 -> 0
A124: 03-05-2026 | B124: EB26050350012878 | C124: 44,000.00 | D124: 2.66 | E124: =C124*D124 -> 117040 | F124: 0.00 | G124: 3.61 | H124: =F124*G124 -> 0
A125: 03-05-2026 | B125: EB26050363156326 | C125: 12,000.00 | D125: 2.66 | E125: =C125*D125 -> 31920 | F125: 0.00 | G125: 3.61 | H125: =F125*G125 -> 0
A126: 03-05-2026 | B126: EB26050338801131 | C126: 17,000.00 | D126: 2.66 | E126: =C126*D126 -> 45220 | F126: 0.00 | G126: 3.61 | H126: =F126*G126 -> 0
A127: 03-05-2026 | B127: BICB260503501469 | C127: 240,000.00 | D127: 2.66 | E127: =C127*D127 -> 638400 | F127: 0.00 | G127: 3.61 | H127: =F127*G127 -> 0
A128: 03-05-2026 | B128: BICB260503627473 | C128: 11,333.00 | D128: 2.66 | E128: =C128*D128 -> 30145.78 | F128: 0.00 | G128: 3.61 | H128: =F128*G128 -> 0
... A254: 24-05-2026 | B254: 146EI24052601121 | C254: 0.00 | D254: 2.66 | E254: =C254*D254 -> 0 | F254: 3,464.01 | G254: 3.61 | H254: =F254*G254 -> 12505.076
E255: =SUM(E117:E254) -> 20382347 | H255: =SUM(H117:H254) -> 20351382
A258: 01-06-2026 | B258: RGI8260601878583 | C258: 0.00 | D258: 5.16 | E258: =C258*D258 -> 0 | F258: 148,277.50 | G258: 5.16 | H258: =F258*G258 -> 765111.9
A259: 01-06-2026 | B259: RGI8260601878635 | C259: 0.00 | D259: 5.16 | E259: =C259*D259 -> 0 | F259: 174,104.75 | G259: =G258 -> 5.16 | H259: =F259*G259 -> 898380.51
A260: 01-06-2026 | B260: 146EI01062642006 | C260: 0.00 | D260: 5.16 | E260: =C260*D260 -> 0 | F260: 18,755.36 | G260: =G259 -> 5.16 | H260: =F260*G260 -> 96777.658
A261: 01-06-2026 | B261: 146EI01062638571 | C261: 0.00 | D261: 5.16 | E261: =C261*D261 -> 0 | F261: 91,021.23 | G261: =G260 -> 5.16 | H261: =F261*G261 -> 469669.55
A262: 01-06-2026 | B262: 146EI01062638776 | C262: 0.00 | D262: 5.16 | E262: =C262*D262 -> 0 | F262: 89.98 | G262: =G261 -> 5.16 | H262: =F262*G262 -> 464.2968
A263: 01-06-2026 | B263: 146EI01062638572 | C263: 0.00 | D263: 5.16 | E263: =C263*D263 -> 0 | F263: 33,594.33 | G263: =G262 -> 5.16 | H263: =F263*G263 -> 173346.74
A264: 01-06-2026 | B264: 146EI01062646286 | C264: 0.00 | D264: 5.16 | E264: =C264*D264 -> 0 | F264: 2,176.02 | G264: =G263 -> 5.16 | H264: =F264*G264 -> 11228.263
A265: 02-06-2026 | B265: 146EI02062655605 | C265: 0.00 | D265: 5.16 | E265: =C265*D265 -> 0 | F265: 21,035.67 | G265: =G264 -> 5.16 | H265: =F265*G265 -> 108544.06
A266: 03-06-2026 | B266: RGI8260603881718 | C266: 0.00 | D266: 5.16 | E266: =C266*D266 -> 0 | F266: 152,467.59 | G266: =G265 -> 5.16 | H266: =F266*G266 -> 786732.76
A267: 04-06-2026 | B267: RGI8260604883398 | C267: 0.00 | D267: 5.16 | E267: =C267*D267 -> 0 | F267: 179,988.35 | G267: =G266 -> 5.16 | H267: =F267*G267 -> 928739.89
A268: 07-06-2026 | B268: RGI8260607885037 | C268: 0.00 | D268: 5.16 | E268: =C268*D268 -> 0 | F268: 145,208.24 | G268: =G267 -> 5.16 | H268: =F268*G268 -> 749274.52
...
